# エラーが発生した場合の処理

プログラムもかなり完成に近づいてきました。住所を取得するという基本的な動作は、
すでに完成されたといっても良いでしょう。

しかし、プログラムを完全な物にするためには、もう一つ重要な要素があります。
エラー処理です。

## 1. 発生するエラーの種類を確認する

試しに、以下のコマンドをターミナルから実行してみて下さい。

```bash
curl "https://zipcloud.ibsnet.co.jp/api/search?zipcode=1111111"
```

結果は次のような物になった筈です。

```bash
{
        "message": null,
        "results": null,
        "status": 200
}
```

どうやら、存在しない郵便番号を入力すると、このように`null`の値が返されるようです。

もう一つ、今度は郵便番号ではない値を API に渡すとどうなるでしょうか。

```bash
> curl "https://zipcloud.ibsnet.co.jp/api/search?zipcode=adcdef" 
{
        "message": "パラメータ「郵便番号」の桁数が不正です。",
        "results": null,
        "status": 400
}
```

今度は`status`が**400**になった上、エラーメッセージが表示されることになりました。

次に、`zip_search.py`を、同じく`1111111`という郵便番号を与えて実行してみましょう。

```bash
> python zip_search.py 
Please input ZIP code for search: 1111111
Traceback (most recent call last):
  File "zip_search.py", line 16, in <module>
    for x in jsons['results']:
TypeError: 'NoneType' object is not iterable
```

エラーが発生してしまいました。
エラーの内容は、`None`タイプのオブジェクトに対する操作エラーであるとされています。
これは、`zip_search.py`が、レスポンスは必ず JSON
形式の文字列であると仮定して作成されているが故に発生したエラーであると言えるでしょう。

このように、正常な値を与えれば正常に動くものの、
異常な値が渡された故にエラーが発生するということは、
プログラム作成において珍しい事ではありません。

当然、こういった事態の対処も、容易に行うことが出来るようになっています。

## 2. try 文による例外（エラー）処理

Python には、`try`文という構文が存在します。

以下のコードを見て下さい。

```py
print(varA)
```

このコードは、`varA`変数に格納された値を print 関数で表示する物ですが、
よく見ると、varA 変数には、何の値も代入されていません。

このコードを実行すると、当然エラーが発生し、
プログラムはそこで異常終了してしまいます。

```bash
Traceback (most recent call last):
  File "<stdin>", line 1, in <module>
NameError: name 'varA' is not defined  # varA 変数が未定義である、というエラー
```

このように、Python はエラー（例外）が発生すると、
その時点で処理が止まってしまうのですが、
エラーが発生していてもプログラムは最後まで動いて欲しい場合もあります。
例えば、正常にデータが取得できるかどうかわからないけど、とりあえず実行して、
その結果を表示してほしい、などの場合が該当するでしょう。

そんな時に使うのが、`try`文という構文です。

```py
try:
  print('Try!')
  print(varA)
except:
  print('...and Error!')
```

try 文を使用する場合は、**エラーが発生するかもしれないコード**を`try:`
以降に記述し、**エラーが発生した場合に行いたい処理**を`except:`以降に記述します。

上記のコードでは、最初の`print('Try!')`は正常に動作するものの、続く`print(varA)`
で先述したエラーが発生してしまうため、実行結果は次のようになります。

```bash
Try!
...and Error!
```

内部的にはエラーが発生しているものの、そこで処理が中断せず、
最後まで実行されている事が確認できました。

では、try 文を使用して、`zip_search.py`を編集してみましょう。

```py
import requests
import json

zipCode = input('Please input ZIP code for search: ')

baseUrl = 'https://zipcloud.ibsnet.co.jp/api/search'
parData = {'zipcode': zipCode, 'limit': 20}

response = requests.get(baseUrl, parData)

jsons = json.loads(response.text)

try:
    i = 1
    for x in jsons['results']:
        print('No. %s' % i)
        print('Zip code: %s' % x['zipcode'])
        print('Address: %s%s%s' % (x['address1'], x['address2'], x['address3']))
        print('Ruby: %s%s%s' % (x['kana1'], x['kana2'], x['kana3']))
        print('')
        i += 1
except:
    print('Error!')
```

このコードを実行した上で、郵便番号に`1111111`や`abcde`を与えてみて下さい。
結果は、どちらも以下のようになる筈です。

```bash
(zip_search)
> python zip_search.py
Please input ZIP code for search: 1111111
Error!
(zip_search)
> python zip_search.py
Please input ZIP code for search: abcde
Error!
```

## 2. if 文によるエラー判別

try 文を使用する事で、
とりあえずエラーによってプログラムが異常終了する事はなくなりました。

しかし、どのような入力をしても`Error!`としか返さないのでは、
一体何が悪かったのかが分かりません。

そこで、エラーメッセージの有無を条件として、動作を分岐させてみましょう。

条件分岐には、`if`文を使用します。

```py
varA = 'Alice'
if varA == 'Bob':
  print('Hello Bob!')
```

上記のコードは、`varA`変数の中身が`Bob`だった場合のみ、`Hello Bob!`
と表示する物です。

varA の中身は`Alice`ですから、このコードを実行しても、
結果は何も表示せずに終了します。

```py
varA = input('What your name?: ')
if varA == 'Bob':
  print('Hello Bob!')
else:
  print('Who are you?')
```

varA 変数への入力を`input`関数で受け取るようにしました。
また、新たに`else:`を加えています。

else: 以下の部分は、**if の条件に合致しなかった場合の処理**を記述しています。

従って、このコードを実行した際の入力として、 Bob と入力すれば "Hello Bob!"
と表示され、それ以外であれば "Who are you?" と表示されるようになります。

ちなみに、if 文の条件を記述するために使用できる記号（比較演算子）には、
以下のような種類が存在します。用途に合わせて使用して下さい。

```text
==      2つのオブジェクトの値が等しいかどうかを調べる
!=      2つのオブジェクトの値が等しくないかどうかを調べる
>       左側の被演算子が右側の被演算子より大きいかどうかを調べる
>=      左側の被演算子が右側の被演算子以上かどうかを調べる
<       左側の被演算子が右側の被演算子よりも小さいかどうかを調べる
<=      左側の演算子が右側の被演算子以下かどうかを調べる
is      2つのオブジェクトが同一のオブジェクトかどうかを調べる
is not  2つのオブジェクトが同一のオブジェクトでないかどうかを調べる
in      左側の被演算子が右側の被演算子に含まれているかどうかを調べる
not in  左側の被演算子が右側の被演算子に含まれていないかどうかを調べる
```

それでは、if 文を使って`zip_search.py`を編集してみましょう。

```py
import requests
import json

zipCode = input('Please input ZIP code for search: ')

baseUrl = 'https://zipcloud.ibsnet.co.jp/api/search'
parData = {'zipcode': zipCode, 'limit': 20}

response = requests.get(baseUrl, parData)

jsons = json.loads(response.text)

try:
    i = 1
    for x in jsons['results']:
        print('No. %s' % i)
        print('Zip code: %s' % x['zipcode'])
        print('Address: %s%s%s' % (x['address1'], x['address2'], x['address3']))
        print('Ruby: %s%s%s' % (x['kana1'], x['kana2'], x['kana3']))
        print('')
        i += 1
except:
    print('Error!')

    if jsons['message'] != None:
        print(jsons['message'])
    else:
        print('指定の郵便番号は存在しません。')
```

`except:`以下の部分に`if`文を追加しました。条件としては、
`message`が無ければ該当する郵便番号が存在しないというメッセージを出力し、
`message`が有ればそれを表示するという物です。

なお、条件として`null`の値指定する場合は、
`None`を指定する必要がある事に注意して下さい。
これは、null の値が、None オブジェクトとして扱われるためです。
従って、`if jsons['message'] != 'null':`としてしまった場合は、
正常に動作しなくなってしまいます。

こうする事で、プログラム全体の動作は次のようになります。

- 郵便番号入力
- API に問い合わせ
  - 正常に郵便番号が検索できた => 結果表示
  - 郵便番号が見つからない => "指定の郵便番号は存在しません。"
  - 入力した番号が不正な形式 => "桁数が不正です。"

```bash
(zip_search)
> python zip_search.py
Please input ZIP code for search: 1111111
Error!
指定の郵便番号は存在しません。
(zip_search)
> python zip_search.py
Please input ZIP code for search: abcde
Error!
パラメータ「郵便番号」の桁数が不正です。
```
